Workbook
Name DateCalc: #REF!:INDEX(#REF!,DAY(DATE(ABREA!$B$11,MATCH(ABREA!$C$11,#REF!,0)+1,0)))
Name DateCalc: #REF!:INDEX(#REF!,DAY(DATE('Accntng Clerk Salary Sample '!$B$11,MATCH('Accntng Clerk Salary Sample '!$C$11,#REF!,0)+1,0)))
Name DateCalc: #REF!:INDEX(#REF!,DAY(DATE(ACOMPAÑADO!$B$11,MATCH(ACOMPAÑADO!$C$11,#REF!,0)+1,0)))
Name DateCalc: Data!$C$2:INDEX(Data!$C$2:$C$32,DAY(DATE(ADELANTAR!$B$11,MATCH(ADELANTAR!$C$11,Data!$B$2:$B$13,0)+1,0)))
Name DateCalc: Data!$C$2:INDEX(Data!$C$2:$C$32,DAY(DATE('ADMIN (2)'!$E$10,MATCH('ADMIN (2)'!$F$10,Data!$B$2:$B$13,0)+1,0)))
Name DateCalc: #REF!:INDEX(#REF!,DAY(DATE(ADRIANO!$B$11,MATCH(ADRIANO!$C$11,#REF!,0)+1,0)))
Name DateCalc: #REF!:INDEX(#REF!,DAY(DATE(ALEJANDRINO!$B$11,MATCH(ALEJANDRINO!$C$11,#REF!,0)+1,0)))
Name DateCalc: #REF!:INDEX(#REF!,DAY(DATE(#REF!,MATCH(#REF!,#REF!,0)+1,0)))
Name DateCalc: #REF!:INDEX(#REF!,DAY(DATE(AURELIO!$B$11,MATCH(AURELIO!$C$11,#REF!,0)+1,0)))
Name DateCalc: #REF!:INDEX(#REF!,DAY(DATE(AZMAN!$B$11,MATCH(AZMAN!$C$11,#REF!,0)+1,0)))
Name DateCalc: #REF!:INDEX(#REF!,DAY(DATE(BARORO!$B$11,MATCH(BARORO!$C$11,#REF!,0)+1,0)))
Name DateCalc: #REF!:INDEX(#REF!,DAY(DATE(BASA!$B$11,MATCH(BASA!$C$11,#REF!,0)+1,0)))
Name DateCalc: Data!$C$2:INDEX(Data!$C$2:$C$32,DAY(DATE(BATUL!$A$10,MATCH(BATUL!$B$10,Data!$B$2:$B$13,0)+1,0)))
Name DateCalc: #REF!:INDEX(#REF!,DAY(DATE(BECARO!$B$11,MATCH(BECARO!$C$11,#REF!,0)+1,0)))
Name DateCalc: Data!$C$2:INDEX(Data!$C$2:$C$32,DAY(DATE('Bi-weekly Timesheet'!$C$9,MATCH('Bi-weekly Timesheet'!$D$9,Data!$B$2:$B$13,0)+1,0)))
Name DateCalc: #REF!:INDEX(#REF!,DAY(DATE(BUNGAY!$B$11,MATCH(BUNGAY!$C$11,#REF!,0)+1,0)))
Name DateCalc: #REF!:INDEX(#REF!,DAY(DATE(CAYAPAS!$B$11,MATCH(CAYAPAS!$C$11,#REF!,0)+1,0)))
Name DateCalc: Data!$C$2:INDEX(Data!$C$2:$C$32,DAY(DATE(COMOSO!$B$11,MATCH(COMOSO!$C$11,Data!$B$2:$B$13,0)+1,0)))
Name DateCalc: #REF!:INDEX(#REF!,DAY(DATE(CONSUELO!$B$11,MATCH(CONSUELO!$C$11,#REF!,0)+1,0)))
Name DateCalc: #REF!:INDEX(#REF!,DAY(DATE(COROSO!$B$11,MATCH(COROSO!$C$11,#REF!,0)+1,0)))
Name DateCalc: Data!$C$2:INDEX(Data!$C$2:$C$32,DAY(DATE(DAGOT!$B$9,MATCH(DAGOT!$C$9,Data!$B$2:$B$13,0)+1,0)))
Name DateCalc: #REF!:INDEX(#REF!,DAY(DATE('DELA CRUZ'!$B$11,MATCH('DELA CRUZ'!$C$11,#REF!,0)+1,0)))
Name DateCalc: #REF!:INDEX(#REF!,DAY(DATE(DIOLA!$B$11,MATCH(DIOLA!$C$11,#REF!,0)+1,0)))
Name DateCalc: #REF!:INDEX(#REF!,DAY(DATE(EDON!$B$10,MATCH(EDON!$C$10,#REF!,0)+1,0)))
Name DateCalc: #REF!:INDEX(#REF!,DAY(DATE(ELEAZAR!$B$11,MATCH(ELEAZAR!$C$11,#REF!,0)+1,0)))
Name DateCalc: Data!$C$2:INDEX(Data!$C$2:$C$32,DAY(DATE(ESTARES!$B$10,MATCH(ESTARES!$C$10,Data!$B$2:$B$13,0)+1,0)))
Name DateCalc: Data!$C$2:INDEX(Data!$C$2:$C$32,DAY(DATE('Fixed Salary - Sample'!$B$10,MATCH('Fixed Salary - Sample'!$C$10,Data!$B$2:$B$13,0)+1,0)))
Name DateCalc: #REF!:INDEX(#REF!,DAY(DATE(GABO!$B$11,MATCH(GABO!$C$11,#REF!,0)+1,0)))
Name DateCalc: #REF!:INDEX(#REF!,DAY(DATE(GAID!$B$11,MATCH(GAID!$C$11,#REF!,0)+1,0)))
Name DateCalc: #REF!:INDEX(#REF!,DAY(DATE(GALLARDO!$B$11,MATCH(GALLARDO!$C$11,#REF!,0)+1,0)))
Name DateCalc: #REF!:INDEX(#REF!,DAY(DATE(GUERZO!$B$11,MATCH(GUERZO!$C$11,#REF!,0)+1,0)))
Name DateCalc: #REF!:INDEX(#REF!,DAY(DATE(HERRERA!$B$11,MATCH(HERRERA!$C$11,#REF!,0)+1,0)))
Name DateCalc: #REF!:INDEX(#REF!,DAY(DATE(LAGROSA!$B$11,MATCH(LAGROSA!$C$11,#REF!,0)+1,0)))
Name DateCalc: #REF!:INDEX(#REF!,DAY(DATE(LEAL!$B$11,MATCH(LEAL!$C$11,#REF!,0)+1,0)))
Name DateCalc: #REF!:INDEX(#REF!,DAY(DATE(MACATANGAY!$B$11,MATCH(MACATANGAY!$C$11,#REF!,0)+1,0)))
Name DateCalc: #REF!:INDEX(#REF!,DAY(DATE(MALAZARTE!$B$11,MATCH(MALAZARTE!$C$11,#REF!,0)+1,0)))
Name DateCalc: #REF!:INDEX(#REF!,DAY(DATE(MOHAMMAD!$B$11,MATCH(MOHAMMAD!$C$11,#REF!,0)+1,0)))
Name DateCalc: #REF!:INDEX(#REF!,DAY(DATE(NICOLAS!$B$11,MATCH(NICOLAS!$C$11,#REF!,0)+1,0)))
Name DateCalc: #REF!:INDEX(#REF!,DAY(DATE(ORBISO!$B$11,MATCH(ORBISO!$C$11,#REF!,0)+1,0)))
Name DateCalc: Data!$C$2:INDEX(Data!$C$2:$C$32,DAY(DATE(PAALAN!$B$11,MATCH(PAALAN!$C$11,Data!$B$2:$B$13,0)+1,0)))
Name DateCalc: #REF!:INDEX(#REF!,DAY(DATE(PAREDES!$B$11,MATCH(PAREDES!$C$11,#REF!,0)+1,0)))
Name DateCalc: Data!$C$2:INDEX(Data!$C$2:$C$32,DAY(DATE(PATRICIO!$B$11,MATCH(PATRICIO!$C$11,Data!$B$2:$B$13,0)+1,0)))
Name DateCalc: Data!$C$2:INDEX(Data!$C$2:$C$32,DAY(DATE('Weekly Timesheet'!$C$9,MATCH('Weekly Timesheet'!$D$9,Data!$B$2:$B$13,0)+1,0)))
Name DateCalc: #REF!:INDEX(#REF!,DAY(DATE(RODRIGUEZ!$B$11,MATCH(RODRIGUEZ!$C$11,#REF!,0)+1,0)))
Name DateCalc: #REF!:INDEX(#REF!,DAY(DATE(RUIZ!$B$11,MATCH(RUIZ!$C$11,#REF!,0)+1,0)))
Name DateCalc: #REF!:INDEX(#REF!,DAY(DATE(#REF!,MATCH(#REF!,#REF!,0)+1,0)))
Name DateCalc: #REF!:INDEX(#REF!,DAY(DATE(SUCIA!$B$11,MATCH(SUCIA!$C$11,#REF!,0)+1,0)))
Name DateCalc: #REF!:INDEX(#REF!,DAY(DATE(TRIPOLI!$B$11,MATCH(TRIPOLI!$C$11,#REF!,0)+1,0)))
Name DateCalc: Data!$C$2:INDEX(Data!$C$2:$C$32,DAY(DATE('Weekly Timesheet'!$C$9,MATCH('Weekly Timesheet'!$D$9,Data!$B$2:$B$13,0)+1,0)))

Sheet Weekly Timesheet
B1: Weekly TimeSheet Calculator
B2: Wayne Enterprise | J2: How to use this template
B3: Employee Name: | D3: Alfred Pennyworth
B4: Department: | D4: Housekeeping | J4: Visit TrumpExcel.com for more Excel Templates
B5: First Line Manager: | D5: Bruce Wayne
C8: Year | D8: Month | E8: Date | F8: Weekend
C9: 2021 | D9: February | E9: 1 | F9: Sat & Sun
C11: Start Time | D11: Regular Hours | E11: Regular Pay (hourly) | F11: Overtime Pay (hourly)
C12: 0.33333333 | D12: 9 | E12: =576.71/8 -> 72.08875 | F12: =(E12*25%)+E12 -> 90.110938
B15: Day | C15: Date | D15: In Time | E15: Out Time | F15: Break Hrs | G15: Regular Hrs | H15: OT Hours | I15: Total Pay
B16: =DATE($C$9,MATCH($D$9,Data!$B$2:$B$13,0),'Weekly Timesheet'!$E$9) -> 44228 | C16: =DATE($C$9,MATCH($D$9,Data!$B$2:$B$13,0),'Weekly Timesheet'!$E$9) -> 44228 | D16: 0.33333333 | E16: 0.70833333 | F16: 1 | G16: =IFERROR(IF(AND(D16<>"",E16<>""),IF(D16>$C$12+TIME($D$12,($D$12-INT($D$12))*60,0),0,IF(E16>$C$12+TIME($D$12,($D$12-INT($D$12))*60,0),MIN(TIME($D$12,($D$12-INT($D$12))*60,0),($C$12+TIME($D$12,($D$12-INT($D$12))*60,0)-D16)),MIN(IF((E16-$C$12)<0,0,(E16-$C$12)),(E16-D16))))*24,"")-F16,"") -> 8 | H16: =IF(AND(D16<>"",E16<>""),((IF(D16<$C$12,MIN($C$12-D16,E16-D16),0)+IF(E16>$C$12+TIME($D$12,($D$12-INT($D$12))*60,0),MIN((E16-$C$12-TIME($D$12,($D$12-INT($D$12))*60,0)),(E16-D16)),0))*24),"") -> 0 | I16: =IFERROR(G16*IF(AND(ISNUMBER(SEARCH(TEXT(B16,"ddd"),$F$9)),Data!$F$2),$F$12,$E$12)+H16*$F$12,"") -> 576.71
B17: =B16+1 -> 44229 | C17: =C16+1 -> 44229 | D17: 0.33333333 | E17: 0.70833333 | F17: 1 | G17: =IFERROR(IF(AND(D17<>"",E17<>""),IF(D17>$C$12+TIME($D$12,($D$12-INT($D$12))*60,0),0,IF(E17>$C$12+TIME($D$12,($D$12-INT($D$12))*60,0),MIN(TIME($D$12,($D$12-INT($D$12))*60,0),($C$12+TIME($D$12,($D$12-INT($D$12))*60,0)-D17)),MIN(IF((E17-$C$12)<0,0,(E17-$C$12)),(E17-D17))))*24,"")-F17,"") -> 8 | H17: =IF(AND(D17<>"",E17<>""),((IF(D17<$C$12,MIN($C$12-D17,E17-D17),0)+IF(E17>$C$12+TIME($D$12,($D$12-INT($D$12))*60,0),MIN((E17-$C$12-TIME($D$12,($D$12-INT($D$12))*60,0)),(E17-D17)),0))*24),"") -> 0 | I17: =IFERROR(G17*IF(AND(ISNUMBER(SEARCH(TEXT(B17,"ddd"),$F$9)),Data!$F$2),$F$12,$E$12)+H17*$F$12,"") -> 576.71
B18: =B17+1 -> 44230 | C18: =C17+1 -> 44230 | D18: 0.33333333 | E18: 0.70833333 | F18: 1 | G18: =IFERROR(IF(AND(D18<>"",E18<>""),IF(D18>$C$12+TIME($D$12,($D$12-INT($D$12))*60,0),0,IF(E18>$C$12+TIME($D$12,($D$12-INT($D$12))*60,0),MIN(TIME($D$12,($D$12-INT($D$12))*60,0),($C$12+TIME($D$12,($D$12-INT($D$12))*60,0)-D18)),MIN(IF((E18-$C$12)<0,0,(E18-$C$12)),(E18-D18))))*24,"")-F18,"") -> 8 | H18: =IF(AND(D18<>"",E18<>""),((IF(D18<$C$12,MIN($C$12-D18,E18-D18),0)+IF(E18>$C$12+TIME($D$12,($D$12-INT($D$12))*60,0),MIN((E18-$C$12-TIME($D$12,($D$12-INT($D$12))*60,0)),(E18-D18)),0))*24),"") -> 0 | I18: =IFERROR(G18*IF(AND(ISNUMBER(SEARCH(TEXT(B18,"ddd"),$F$9)),Data!$F$2),$F$12,$E$12)+H18*$F$12,"") -> 576.71
B19: =B18+1 -> 44231 | C19: =C18+1 -> 44231 | D19: 0.33333333 | E19: 0.70833333 | F19: 1 | G19: =IFERROR(IF(AND(D19<>"",E19<>""),IF(D19>$C$12+TIME($D$12,($D$12-INT($D$12))*60,0),0,IF(E19>$C$12+TIME($D$12,($D$12-INT($D$12))*60,0),MIN(TIME($D$12,($D$12-INT($D$12))*60,0),($C$12+TIME($D$12,($D$12-INT($D$12))*60,0)-D19)),MIN(IF((E19-$C$12)<0,0,(E19-$C$12)),(E19-D19))))*24,"")-F19,"") -> 8 | H19: =IF(AND(D19<>"",E19<>""),((IF(D19<$C$12,MIN($C$12-D19,E19-D19),0)+IF(E19>$C$12+TIME($D$12,($D$12-INT($D$12))*60,0),MIN((E19-$C$12-TIME($D$12,($D$12-INT($D$12))*60,0)),(E19-D19)),0))*24),"") -> 0 | I19: =IFERROR(G19*IF(AND(ISNUMBER(SEARCH(TEXT(B19,"ddd"),$F$9)),Data!$F$2),$F$12,$E$12)+H19*$F$12,"") -> 576.71
B20: =B19+1 -> 44232 | C20: =C19+1 -> 44232 | D20: 0.33333333 | E20: 0.70833333 | F20: 1 | G20: =IFERROR(IF(AND(D20<>"",E20<>""),IF(D20>$C$12+TIME($D$12,($D$12-INT($D$12))*60,0),0,IF(E20>$C$12+TIME($D$12,($D$12-INT($D$12))*60,0),MIN(TIME($D$12,($D$12-INT($D$12))*60,0),($C$12+TIME($D$12,($D$12-INT($D$12))*60,0)-D20)),MIN(IF((E20-$C$12)<0,0,(E20-$C$12)),(E20-D20))))*24,"")-F20,"") -> 8 | H20: =IF(AND(D20<>"",E20<>""),((IF(D20<$C$12,MIN($C$12-D20,E20-D20),0)+IF(E20>$C$12+TIME($D$12,($D$12-INT($D$12))*60,0),MIN((E20-$C$12-TIME($D$12,($D$12-INT($D$12))*60,0)),(E20-D20)),0))*24),"") -> 0 | I20: =IFERROR(G20*IF(AND(ISNUMBER(SEARCH(TEXT(B20,"ddd"),$F$9)),Data!$F$2),$F$12,$E$12)+H20*$F$12,"") -> 576.71
B21: =B20+1 -> 44233 | C21: =C20+1 -> 44233 | D21: 0.33333333 | E21: 0.70833333 | F21: 1 | G21: =IFERROR(IF(AND(D21<>"",E21<>""),IF(D21>$C$12+TIME($D$12,($D$12-INT($D$12))*60,0),0,IF(E21>$C$12+TIME($D$12,($D$12-INT($D$12))*60,0),MIN(TIME($D$12,($D$12-INT($D$12))*60,0),($C$12+TIME($D$12,($D$12-INT($D$12))*60,0)-D21)),MIN(IF((E21-$C$12)<0,0,(E21-$C$12)),(E21-D21))))*24,"")-F21,"") -> 8 | H21: =IF(AND(D21<>"",E21<>""),((IF(D21<$C$12,MIN($C$12-D21,E21-D21),0)+IF(E21>$C$12+TIME($D$12,($D$12-INT($D$12))*60,0),MIN((E21-$C$12-TIME($D$12,($D$12-INT($D$12))*60,0)),(E21-D21)),0))*24),"") -> 0 | I21: =IFERROR(G21*IF(AND(ISNUMBER(SEARCH(TEXT(B21,"ddd"),$F$9)),Data!$F$2),$F$12,$E$12)+H21*$F$12,"") -> 720.8875
B22: =B21+1 -> 44234 | C22: =C21+1 -> 44234 | G22: =IFERROR(IF(AND(D22<>"",E22<>""),IF(D22>$C$12+TIME($D$12,($D$12-INT($D$12))*60,0),0,IF(E22>$C$12+TIME($D$12,($D$12-INT($D$12))*60,0),MIN(TIME($D$12,($D$12-INT($D$12))*60,0),($C$12+TIME($D$12,($D$12-INT($D$12))*60,0)-D22)),MIN(IF((E22-$C$12)<0,0,(E22-$C$12)),(E22-D22))))*24,"")-F22,"") | H22: =IF(AND(D22<>"",E22<>""),((IF(D22<$C$12,MIN($C$12-D22,E22-D22),0)+IF(E22>$C$12+TIME($D$12,($D$12-INT($D$12))*60,0),MIN((E22-$C$12-TIME($D$12,($D$12-INT($D$12))*60,0)),(E22-D22)),0))*24),"") | I22: =IFERROR(G22*IF(AND(ISNUMBER(SEARCH(TEXT(B22,"ddd"),$F$9)),Data!$F$2),$F$12,$E$12)+H22*$F$12,"")
E24: Weekly Summary | F24: =SUM(F16:F22) -> 6 | G24: =SUM(G16:G22) -> 48 | H24: =SUM(H16:H22) -> 0 | I24: =SUM(I16:I22) -> 3604.4375

Sheet Bi-weekly Timesheet
B1: Weekly TimeSheet Calculator
B2: [Company Name] | J2: How to use this template
B3: Employee Name:
B4: Department: | J4: Visit TrumpExcel.com for more Excel Templates
B5: First Line Manager:
C8: Year | D8: Month | E8: Date | F8: Weekend
C9: 2022 | D9: April | E9: 10 | F9: Sat & Sun
C11: Start Time | D11: Regular Hours | E11: Regular Pay (hourly) | F11: Overtime Pay (hourly)
C12: 0.375 | D12: 6.5 | E12: 30 | F12: 50
B15: Day | C15: Date | D15: In Time | E15: Out Time | F15: Break Hrs | G15: Regular Hrs | H15: OT Hours | I15: Total Pay
B16: =DATE($C$9,MATCH($D$9,Data!$B$2:$B$13,0),'Bi-weekly Timesheet'!$E$9) -> 44661 | C16: =DATE($C$9,MATCH($D$9,Data!$B$2:$B$13,0),'Bi-weekly Timesheet'!$E$9) -> 44661 | D16: 0.375 | E16: 0.75 | F16: 1 | G16: =IFERROR(IF(AND(D16<>"",E16<>""),IF(D16>$C$12+TIME($D$12,($D$12-INT($D$12))*60,0),0,IF(E16>$C$12+TIME($D$12,($D$12-INT($D$12))*60,0),MIN(TIME($D$12,($D$12-INT($D$12))*60,0),($C$12+TIME($D$12,($D$12-INT($D$12))*60,0)-D16)),MIN(IF((E16-$C$12)<0,0,(E16-$C$12)),(E16-D16))))*24,"")-F16,"") -> 5.5 | H16: =IF(AND(D16<>"",E16<>""),((IF(D16<$C$12,MIN($C$12-D16,E16-D16),0)+IF(E16>$C$12+TIME($D$12,($D$12-INT($D$12))*60,0),MIN((E16-$C$12-TIME($D$12,($D$12-INT($D$12))*60,0)),(E16-D16)),0))*24),"") -> 2.5 | I16: =IFERROR(G16*IF(AND(ISNUMBER(SEARCH(TEXT(B16,"ddd"),$F$9)),Data!$F$2),$F$12,$E$12)+H16*$F$12,"") -> 400
B17: =B16+1 -> 44662 | C17: =C16+1 -> 44662 | G17: =IFERROR(IF(AND(D17<>"",E17<>""),IF(D17>$C$12+TIME($D$12,($D$12-INT($D$12))*60,0),0,IF(E17>$C$12+TIME($D$12,($D$12-INT($D$12))*60,0),MIN(TIME($D$12,($D$12-INT($D$12))*60,0),($C$12+TIME($D$12,($D$12-INT($D$12))*60,0)-D17)),MIN(IF((E17-$C$12)<0,0,(E17-$C$12)),(E17-D17))))*24,"")-F17,"") | H17: =IF(AND(D17<>"",E17<>""),((IF(D17<$C$12,MIN($C$12-D17,E17-D17),0)+IF(E17>$C$12+TIME($D$12,($D$12-INT($D$12))*60,0),MIN((E17-$C$12-TIME($D$12,($D$12-INT($D$12))*60,0)),(E17-D17)),0))*24),"") | I17: =IFERROR(G17*IF(AND(ISNUMBER(SEARCH(TEXT(B17,"ddd"),$F$9)),Data!$F$2),$F$12,$E$12)+H17*$F$12,"")
B18: =B17+1 -> 44663 | C18: =C17+1 -> 44663 | G18: =IFERROR(IF(AND(D18<>"",E18<>""),IF(D18>$C$12+TIME($D$12,($D$12-INT($D$12))*60,0),0,IF(E18>$C$12+TIME($D$12,($D$12-INT($D$12))*60,0),MIN(TIME($D$12,($D$12-INT($D$12))*60,0),($C$12+TIME($D$12,($D$12-INT($D$12))*60,0)-D18)),MIN(IF((E18-$C$12)<0,0,(E18-$C$12)),(E18-D18))))*24,"")-F18,"") | H18: =IF(AND(D18<>"",E18<>""),((IF(D18<$C$12,MIN($C$12-D18,E18-D18),0)+IF(E18>$C$12+TIME($D$12,($D$12-INT($D$12))*60,0),MIN((E18-$C$12-TIME($D$12,($D$12-INT($D$12))*60,0)),(E18-D18)),0))*24),"") | I18: =IFERROR(G18*IF(AND(ISNUMBER(SEARCH(TEXT(B18,"ddd"),$F$9)),Data!$F$2),$F$12,$E$12)+H18*$F$12,"")
B19: =B18+1 -> 44664 | C19: =C18+1 -> 44664 | G19: =IFERROR(IF(AND(D19<>"",E19<>""),IF(D19>$C$12+TIME($D$12,($D$12-INT($D$12))*60,0),0,IF(E19>$C$12+TIME($D$12,($D$12-INT($D$12))*60,0),MIN(TIME($D$12,($D$12-INT($D$12))*60,0),($C$12+TIME($D$12,($D$12-INT($D$12))*60,0)-D19)),MIN(IF((E19-$C$12)<0,0,(E19-$C$12)),(E19-D19))))*24,"")-F19,"") | H19: =IF(AND(D19<>"",E19<>""),((IF(D19<$C$12,MIN($C$12-D19,E19-D19),0)+IF(E19>$C$12+TIME($D$12,($D$12-INT($D$12))*60,0),MIN((E19-$C$12-TIME($D$12,($D$12-INT($D$12))*60,0)),(E19-D19)),0))*24),"") | I19: =IFERROR(G19*IF(AND(ISNUMBER(SEARCH(TEXT(B19,"ddd"),$F$9)),Data!$F$2),$F$12,$E$12)+H19*$F$12,"")
B20: =B19+1 -> 44665 | C20: =C19+1 -> 44665 | G20: =IFERROR(IF(AND(D20<>"",E20<>""),IF(D20>$C$12+TIME($D$12,($D$12-INT($D$12))*60,0),0,IF(E20>$C$12+TIME($D$12,($D$12-INT($D$12))*60,0),MIN(TIME($D$12,($D$12-INT($D$12))*60,0),($C$12+TIME($D$12,($D$12-INT($D$12))*60,0)-D20)),MIN(IF((E20-$C$12)<0,0,(E20-$C$12)),(E20-D20))))*24,"")-F20,"") | H20: =IF(AND(D20<>"",E20<>""),((IF(D20<$C$12,MIN($C$12-D20,E20-D20),0)+IF(E20>$C$12+TIME($D$12,($D$12-INT($D$12))*60,0),MIN((E20-$C$12-TIME($D$12,($D$12-INT($D$12))*60,0)),(E20-D20)),0))*24),"") | I20: =IFERROR(G20*IF(AND(ISNUMBER(SEARCH(TEXT(B20,"ddd"),$F$9)),Data!$F$2),$F$12,$E$12)+H20*$F$12,"")
B21: =B20+1 -> 44666 | C21: =C20+1 -> 44666 | G21: =IFERROR(IF(AND(D21<>"",E21<>""),IF(D21>$C$12+TIME($D$12,($D$12-INT($D$12))*60,0),0,IF(E21>$C$12+TIME($D$12,($D$12-INT($D$12))*60,0),MIN(TIME($D$12,($D$12-INT($D$12))*60,0),($C$12+TIME($D$12,($D$12-INT($D$12))*60,0)-D21)),MIN(IF((E21-$C$12)<0,0,(E21-$C$12)),(E21-D21))))*24,"")-F21,"") | H21: =IF(AND(D21<>"",E21<>""),((IF(D21<$C$12,MIN($C$12-D21,E21-D21),0)+IF(E21>$C$12+TIME($D$12,($D$12-INT($D$12))*60,0),MIN((E21-$C$12-TIME($D$12,($D$12-INT($D$12))*60,0)),(E21-D21)),0))*24),"") | I21: =IFERROR(G21*IF(AND(ISNUMBER(SEARCH(TEXT(B21,"ddd"),$F$9)),Data!$F$2),$F$12,$E$12)+H21*$F$12,"")
B22: =B21+1 -> 44667 | C22: =C21+1 -> 44667 | G22: =IFERROR(IF(AND(D22<>"",E22<>""),IF(D22>$C$12+TIME($D$12,($D$12-INT($D$12))*60,0),0,IF(E22>$C$12+TIME($D$12,($D$12-INT($D$12))*60,0),MIN(TIME($D$12,($D$12-INT($D$12))*60,0),($C$12+TIME($D$12,($D$12-INT($D$12))*60,0)-D22)),MIN(IF((E22-$C$12)<0,0,(E22-$C$12)),(E22-D22))))*24,"")-F22,"") | H22: =IF(AND(D22<>"",E22<>""),((IF(D22<$C$12,MIN($C$12-D22,E22-D22),0)+IF(E22>$C$12+TIME($D$12,($D$12-INT($D$12))*60,0),MIN((E22-$C$12-TIME($D$12,($D$12-INT($D$12))*60,0)),(E22-D22)),0))*24),"") | I22: =IFERROR(G22*IF(AND(ISNUMBER(SEARCH(TEXT(B22,"ddd"),$F$9)),Data!$F$2),$F$12,$E$12)+H22*$F$12,"")
B23: =B22+1 -> 44668 | C23: =C22+1 -> 44668 | G23: =IFERROR(IF(AND(D23<>"",E23<>""),IF(D23>$C$12+TIME($D$12,($D$12-INT($D$12))*60,0),0,IF(E23>$C$12+TIME($D$12,($D$12-INT($D$12))*60,0),MIN(TIME($D$12,($D$12-INT($D$12))*60,0),($C$12+TIME($D$12,($D$12-INT($D$12))*60,0)-D23)),MIN(IF((E23-$C$12)<0,0,(E23-$C$12)),(E23-D23))))*24,"")-F23,"") | H23: =IF(AND(D23<>"",E23<>""),((IF(D23<$C$12,MIN($C$12-D23,E23-D23),0)+IF(E23>$C$12+TIME($D$12,($D$12-INT($D$12))*60,0),MIN((E23-$C$12-TIME($D$12,($D$12-INT($D$12))*60,0)),(E23-D23)),0))*24),"") | I23: =IFERROR(G23*IF(AND(ISNUMBER(SEARCH(TEXT(B23,"ddd"),$F$9)),Data!$F$2),$F$12,$E$12)+H23*$F$12,"")
B24: =B23+1 -> 44669 | C24: =C23+1 -> 44669 | G24: =IFERROR(IF(AND(D24<>"",E24<>""),IF(D24>$C$12+TIME($D$12,($D$12-INT($D$12))*60,0),0,IF(E24>$C$12+TIME($D$12,($D$12-INT($D$12))*60,0),MIN(TIME($D$12,($D$12-INT($D$12))*60,0),($C$12+TIME($D$12,($D$12-INT($D$12))*60,0)-D24)),MIN(IF((E24-$C$12)<0,0,(E24-$C$12)),(E24-D24))))*24,"")-F24,"") | H24: =IF(AND(D24<>"",E24<>""),((IF(D24<$C$12,MIN($C$12-D24,E24-D24),0)+IF(E24>$C$12+TIME($D$12,($D$12-INT($D$12))*60,0),MIN((E24-$C$12-TIME($D$12,($D$12-INT($D$12))*60,0)),(E24-D24)),0))*24),"") | I24: =IFERROR(G24*IF(AND(ISNUMBER(SEARCH(TEXT(B24,"ddd"),$F$9)),Data!$F$2),$F$12,$E$12)+H24*$F$12,"")
B25: =B24+1 -> 44670 | C25: =C24+1 -> 44670 | G25: =IFERROR(IF(AND(D25<>"",E25<>""),IF(D25>$C$12+TIME($D$12,($D$12-INT($D$12))*60,0),0,IF(E25>$C$12+TIME($D$12,($D$12-INT($D$12))*60,0),MIN(TIME($D$12,($D$12-INT($D$12))*60,0),($C$12+TIME($D$12,($D$12-INT($D$12))*60,0)-D25)),MIN(IF((E25-$C$12)<0,0,(E25-$C$12)),(E25-D25))))*24,"")-F25,"") | H25: =IF(AND(D25<>"",E25<>""),((IF(D25<$C$12,MIN($C$12-D25,E25-D25),0)+IF(E25>$C$12+TIME($D$12,($D$12-INT($D$12))*60,0),MIN((E25-$C$12-TIME($D$12,($D$12-INT($D$12))*60,0)),(E25-D25)),0))*24),"") | I25: =IFERROR(G25*IF(AND(ISNUMBER(SEARCH(TEXT(B25,"ddd"),$F$9)),Data!$F$2),$F$12,$E$12)+H25*$F$12,"")
B26: =B25+1 -> 44671 | C26: =C25+1 -> 44671 | G26: =IFERROR(IF(AND(D26<>"",E26<>""),IF(D26>$C$12+TIME($D$12,($D$12-INT($D$12))*60,0),0,IF(E26>$C$12+TIME($D$12,($D$12-INT($D$12))*60,0),MIN(TIME($D$12,($D$12-INT($D$12))*60,0),($C$12+TIME($D$12,($D$12-INT($D$12))*60,0)-D26)),MIN(IF((E26-$C$12)<0,0,(E26-$C$12)),(E26-D26))))*24,"")-F26,"") | H26: =IF(AND(D26<>"",E26<>""),((IF(D26<$C$12,MIN($C$12-D26,E26-D26),0)+IF(E26>$C$12+TIME($D$12,($D$12-INT($D$12))*60,0),MIN((E26-$C$12-TIME($D$12,($D$12-INT($D$12))*60,0)),(E26-D26)),0))*24),"") | I26: =IFERROR(G26*IF(AND(ISNUMBER(SEARCH(TEXT(B26,"ddd"),$F$9)),Data!$F$2),$F$12,$E$12)+H26*$F$12,"")
B27: =B26+1 -> 44672 | C27: =C26+1 -> 44672 | G27: =IFERROR(IF(AND(D27<>"",E27<>""),IF(D27>$C$12+TIME($D$12,($D$12-INT($D$12))*60,0),0,IF(E27>$C$12+TIME($D$12,($D$12-INT($D$12))*60,0),MIN(TIME($D$12,($D$12-INT($D$12))*60,0),($C$12+TIME($D$12,($D$12-INT($D$12))*60,0)-D27)),MIN(IF((E27-$C$12)<0,0,(E27-$C$12)),(E27-D27))))*24,"")-F27,"") | H27: =IF(AND(D27<>"",E27<>""),((IF(D27<$C$12,MIN($C$12-D27,E27-D27),0)+IF(E27>$C$12+TIME($D$12,($D$12-INT($D$12))*60,0),MIN((E27-$C$12-TIME($D$12,($D$12-INT($D$12))*60,0)),(E27-D27)),0))*24),"") | I27: =IFERROR(G27*IF(AND(ISNUMBER(SEARCH(TEXT(B27,"ddd"),$F$9)),Data!$F$2),$F$12,$E$12)+H27*$F$12,"")
B28: =B27+1 -> 44673 | C28: =C27+1 -> 44673 | G28: =IFERROR(IF(AND(D28<>"",E28<>""),IF(D28>$C$12+TIME($D$12,($D$12-INT($D$12))*60,0),0,IF(E28>$C$12+TIME($D$12,($D$12-INT($D$12))*60,0),MIN(TIME($D$12,($D$12-INT($D$12))*60,0),($C$12+TIME($D$12,($D$12-INT($D$12))*60,0)-D28)),MIN(IF((E28-$C$12)<0,0,(E28-$C$12)),(E28-D28))))*24,"")-F28,"") | H28: =IF(AND(D28<>"",E28<>""),((IF(D28<$C$12,MIN($C$12-D28,E28-D28),0)+IF(E28>$C$12+TIME($D$12,($D$12-INT($D$12))*60,0),MIN((E28-$C$12-TIME($D$12,($D$12-INT($D$12))*60,0)),(E28-D28)),0))*24),"") | I28: =IFERROR(G28*IF(AND(ISNUMBER(SEARCH(TEXT(B28,"ddd"),$F$9)),Data!$F$2),$F$12,$E$12)+H28*$F$12,"")
B29: =B28+1 -> 44674 | C29: =C28+1 -> 44674 | G29: =IFERROR(IF(AND(D29<>"",E29<>""),IF(D29>$C$12+TIME($D$12,($D$12-INT($D$12))*60,0),0,IF(E29>$C$12+TIME($D$12,($D$12-INT($D$12))*60,0),MIN(TIME($D$12,($D$12-INT($D$12))*60,0),($C$12+TIME($D$12,($D$12-INT($D$12))*60,0)-D29)),MIN(IF((E29-$C$12)<0,0,(E29-$C$12)),(E29-D29))))*24,"")-F29,"") | H29: =IF(AND(D29<>"",E29<>""),((IF(D29<$C$12,MIN($C$12-D29,E29-D29),0)+IF(E29>$C$12+TIME($D$12,($D$12-INT($D$12))*60,0),MIN((E29-$C$12-TIME($D$12,($D$12-INT($D$12))*60,0)),(E29-D29)),0))*24),"") | I29: =IFERROR(G29*IF(AND(ISNUMBER(SEARCH(TEXT(B29,"ddd"),$F$9)),Data!$F$2),$F$12,$E$12)+H29*$F$12,"")
E31: Bi-weekly Summary | F31: =SUM(F16:F29) -> 1 | G31: =SUM(G16:G29) -> 5.5 | H31: =SUM(H16:H29) -> 2.5 | I31: =SUM(I16:I29) -> 400

Sheet 15
B3: BACS CONSTRUCTION SERVICES AND ENGINEERING CONSULTANCY
B4: PAYROLL SUMMARY
B5: COVERED DATE : | C5: AUG. 11-25, 2022
B6: PERIOD : | C6: 44804
B8: NAME | C8: DESIGNATION | D8: Hours/Days | E8: Basic Pay | F8: Less: Absent, Late and Undertime | G8: Total Basic Pay | H8: Overtime | I8: Holiday & Premium Pay | J8: GROSS WAGE | K8: De Minimis | O8: DEDUCTIONS | U8: TOTAL DEDUCTION | V8: NET PAY
L10: PHIC | M10: HDMF | N10: INSURANCE | O10: Income Tax | P10: COMM. ALLOWANCE | Q10: Other Deduction | R10: SSS Loan | S10: CASH ADVANCE/LOAN | T10: FOR RETRO
N11: BPI
B13: Bacosa , Cesario Jr | C13: CEO/ PRESIDENT | E13: 15000 | K13: 2500 | N13: 147.17 | P13: 899.75 | Q13: 5000 | U13: =SUM(L13:S13) -> 6046.92 | V13: =(E13+K13)-U13 -> 11453.08
B14: Villegas, Gabby G. | C14: Project Manager | E14: 13250 | K14: 4250 | L14: 397.5 | M14: 300 | N14: 147.17 | O14: =1133.33/2 -> 566.665 | P14: =500/2 -> 250 | Q14: 187.5 | S14: 1791.67 | U14: =SUM(L14:S14) -> 3640.505 | V14: =(E14+K14)-U14 -> 13859.495
B15: Germina, Mark Jayson H | C15: Operation Manager | E15: 11250 | K15: 4250 | L15: 337.5 | M15: 300 | N15: 147.17 | O15: =533.4/2 -> 266.7 | P15: =500/2 -> 250 | Q15: 187.5 | S15: 1770.83 | U15: =SUM(L15:S15) -> 3259.7 | V15: =(E15+K15)-U15 -> 12240.3
B16: Beltran, Lyn M. | C16: Admin Manager | E16: 12750 | K16: 4250 | L16: 382.5 | M16: 500 | N16: 147.17 | O16: =1133.33/2 -> 566.665 | P16: 250 | S16: 3480 | U16: =SUM(L16:S16) -> 5326.335 | V16: =(E16+K16)-U16 -> 11673.665
B17: Bacosa, Katherine J. | C17: Finance Manager | E17: 11000 | K17: 3500 | N17: 147.17 | P17: 837.25 | Q17: 5000 | S17: 1500 | U17: =SUM(L17:S17) -> 7484.42 | V17: =(E17+K17)-U17 -> 7015.58
B18: PROJECT MANAGEMENT | V18: =(E18+K18)-U18 -> 0
B19: Bocala, Kevin O. | C19: Technical Head | E19: 9000 | F19: =#REF! -> #REF! | G19: =E19-F19 -> #REF! | J19: =G19+H19+I19 -> #REF! | L19: 225 | M19: 100 | N19: 109.23 | U19: =SUM(L19:S19) -> 434.23 | V19: =(J19+K19)-U19 -> #REF!
B20: Comoso, Mayca | C20: Office Staff | E20: =COMOSO!N34 -> 7045.3846 | F20: =COMOSO!N35 -> 327.69231 | G20: =E20-F20 -> 6717.6923 | H20: =COMOSO!N37 -> 0 | I20: =COMOSO!N38 -> 1474.6154 | J20: =G20+H20+I20 -> 8192.3077 | L20: 225.64 | M20: 100 | N20: 71.29 | U20: =SUM(L20:S20) -> 396.93 | V20: =(J20+K20)-U20 -> 7795.3777
B21: Dagot, Gie Boy | C21: Technical Staff | E21: =DAGOT!N37 -> 11087.238 | F21: =DAGOT!N38 -> 596.79456 | G21: =E21-F21 -> 10490.444 | I21: =DAGOT!N41 -> 0 | J21: =G21+H21+I21 -> 10490.444 | L21: 225.64 | M21: 100 | N21: 71.29 | U21: =SUM(L21:S21) -> 396.93 | V21: =(J21+K21)-U21 -> 10093.514
B22: Sucia, Van Lloyd | C22: Technical Staff | E22: =#REF! -> #REF! | F22: =#REF! -> #REF! | G22: =E22-F22 -> #REF! | I22: =#REF! -> #REF! | J22: =G22+H22+I22 -> #REF! | L22: 225.64 | M22: 100 | N22: 71.29 | U22: =SUM(L22:S22) -> 396.93 | V22: =(J22+K22)-U22 -> #REF!
B23: Malazarte, Jan Kayle Mari | C23: Technical Staff | E23: =#REF! -> #REF! | F23: =#REF! -> #REF! | G23: =E23-F23 -> #REF! | I23: =#REF! -> #REF! | J23: =G23+H23+I23 -> #REF! | L23: 225.64 | M23: 100 | N23: 71.29 | U23: =SUM(L23:S23) -> 396.93 | V23: =(J23+K23)-U23 -> #REF!
B24: Soledad, Princess Joy | C24: Project Survey Head | E24: 10250 | G24: =E24-F24 -> 10250 | J24: =G24+H24+I24 -> 10250 | L24: 307.5 | M24: 100 | N24: 109.23 | U24: =SUM(L24:S24) -> 516.73 | V24: =(J24+K24)-U24 -> 9733.27
B25: Batul, Shajanli Grace | C25: Procurement Officer | E25: =BATUL!M32 -> 10020 | F25: =BATUL!M33 -> 0 | G25: =E25-F25 -> 10020 | H25: =BATUL!M35 -> 0 | I25: =BATUL!M36 -> 0 | J25: =G25+H25+I25 -> 10020 | L25: 180 | M25: 100 | N25: 142.58 | U25: =SUM(L25:S25) -> 422.58 | V25: =(J25+K25)-U25 -> 9597.42
B26: Juanich, Paul Jerome | C26: Draftsman | E26: =#REF! -> #REF! | F26: =#REF! -> #REF! | G26: =E26-F26 -> #REF! | I26: =#REF! -> #REF! | J26: =G26+H26+I26 -> #REF! | N26: 285.16 | U26: =SUM(L26:S26) -> 285.16 | V26: =(J26+K26)-U26 -> #REF!
B27: Manaeg, Harold | C27: Technical Staff | E27: =ADELANTAR!N34 -> 4305 | F27: =ADELANTAR!N35 -> 312.28333 | G27: =E27-F27 -> 3992.7167 | H27: =ADELANTAR!N37 -> 153.75 | I27: =ADELANTAR!N38 -> 0 | J27: =G27+H27+I27 -> 4146.4667 | L27: 180 | M27: 100 | N27: 285.16 | U27: =SUM(L27:S27) -> 565.16 | V27: =(J27+K27)-U27 -> 3581.3067
B28: Alejandrino, Rey Mark | C28: Laboratory Operator | E28: =#REF! -> #REF! | F28: =#REF! -> #REF! | G28: =E28-F28 -> #REF! | H28: =#REF! -> #REF! | I28: =#REF! -> #REF! | J28: =G28+H28+I28 -> #REF! | L28: 180 | M28: 100 | N28: 171.1 | U28: =SUM(L28:S28) -> 451.1 | V28: =(J28+K28)-U28 -> #REF!
B29: Paredes, Matthew | C29: Part Time Draftsman | E29: =#REF! -> #REF! | F29: =#REF! -> #REF! | G29: =E29-F29 -> #REF! | H29: =#REF! -> #REF! | I29: =#REF! -> #REF! | J29: =G29+H29+I29 -> #REF!
B30: ADMIN | G30: =E30-F30 -> 0 | J30: =G30+H30+I30 -> 0 | V30: =(J30+K30)-U30 -> 0
B31: Gaid, Dorabel Y. | C31: Admin Assistant | E31: =#REF! -> #REF! | F31: =#REF! -> #REF! | G31: =E31-F31 -> #REF! | H31: =#REF! -> #REF! | I31: =#REF! -> #REF! | J31: =G31+H31+I31 -> #REF! | L31: 240 | M31: 500 | N31: 147.17 | R31: 1015.19 | S31: 1000 | U31: =SUM(L31:S31) -> 2902.36 | V31: =(J31+K31)-U31 -> #REF!
B32: Guerzo, Jovelyn H. | C32: EHS Head | E32: 9250 | G32: =E32-F32 -> 9250 | J32: =G32+H32+I32 -> 9250 | L32: 277.5 | M32: 100 | N32: 109.23 | U32: =SUM(L32:S32) -> 486.73 | V32: =(J32+K32)-U32 -> 8763.27
B33: Jamelo, Elfren | C33: Amansinaya In-charge | E33: 7500 | G33: =E33-F33 -> 7500 | J33: =G33+H33+I33 -> 7500 | K33: 2000 | L33: 225 | N33: 109.23 | U33: =SUM(L33:S33) -> 334.23 | V33: =(J33+K33)-U33 -> 9165.77
B34: Macatangay, Michael | C34: Company Driver | E34: 7500 | G34: =E34-F34 -> 7500 | J34: =G34+H34+I34 -> 7500 | K34: 1000 | L34: 225 | M34: 100 | N34: 142.58 | U34: =SUM(L34:S34) -> 467.58 | V34: =(J34+K34)-U34 -> 8032.42
B35: Galedo, Joshua | C35: General Services Staff | E35: 7500 | F35: =#REF! -> #REF! | G35: =E35-F35 -> #REF! | J35: =G35+H35+I35 -> #REF! | L35: 225 | M35: 100 | N35: 71.29 | U35: =SUM(L35:S35) -> 396.29 | V35: =(J35+K35)-U35 -> #REF!
B36: Aurelio, Roderic | C36: Utility | E36: =#REF! -> #REF! | F36: =#REF! -> #REF! | G36: =E36-F36 -> #REF! | I36: =#REF! -> #REF! | J36: =G36+H36+I36 -> #REF! | L36: 150 | M36: 100 | U36: =SUM(L36:S36) -> 250 | V36: =(J36+K36)-U36 -> #REF!
B37: FINANCE | G37: =E37-F37 -> 0 | J37: =G37+H37+I37 -> 0 | V37: =(J37+K37)-U37 -> 0
B38: Acompañado, Nancy | C38: A/R Officer | E38: =#REF! -> #REF! | F38: =#REF! -> #REF! | G38: =E38-F38 -> #REF! | H38: =#REF! -> #REF! | I38: =#REF! -> #REF! | J38: =G38+H38+I38 -> #REF! | L38: 240 | M38: 100 | N38: 71.29 | Q38: 292 | U38: =SUM(L38:S38) -> 703.29 | V38: =(J38+K38)-U38 -> #REF!
B39: Consuelo, Regine | C39: Finance Assistant | E39: 8500 | F39: =#REF! -> #REF! | G39: =E39-F39 -> #REF! | J39: =G39+H39+I39 -> #REF! | L39: 255 | M39: 100 | N39: 71.29 | Q39: 292 | U39: =SUM(L39:S39) -> 718.29 | V39: =(J39+K39)-U39 -> #REF!
B40: Dobleros, Reden | C40: Accounting Clerk | E40: =#REF! -> #REF! | F40: =#REF! -> #REF! | G40: =E40-F40 -> #REF! | H40: =#REF! -> #REF! | I40: =#REF! -> #REF! | J40: =G40+H40+I40 -> #REF! | L40: 180 | M40: 100 | N40: 142.58 | U40: =SUM(L40:S40) -> 422.58 | V40: =(J40+K40)-U40 -> #REF!
B41: OPERATION | G41: =E41-F41 -> 0 | J41: =G41+H41+I41 -> 0 | V41: =(J41+K41)-U41 -> 0
B42: Cayapas, Reymond I | C42: Project Team Leader | D42: =#REF! -> #REF! | E42: =#REF! -> #REF! | F42: =#REF! -> #REF! | G42: =E42-F42 -> #REF! | J42: =G42+H42+I42 -> #REF! | L42: 180 | M42: 100 | U42: =SUM(L42:S42) -> 280 | V42: =(J42+K42)-U42 -> #REF!
B43: Morados, Moses | C43: Laborer | D43: =#REF! -> #REF! | E43: =#REF! -> #REF! | F43: =#REF! -> #REF! | G43: =E43-F43 -> #REF! | I43: =#REF! -> #REF! | J43: =G43+H43+I43 -> #REF! | L43: 180 | U43: =SUM(L43:S43) -> 180 | V43: =(J43+K43)-U43 -> #REF!
B44: Suprecencia, Melvin | C44: Project Supervisor | D44: 12D | E44: 8500 | G44: =E44-F44 -> 8500 | K44: 2500 | L44: 255 | M44: 100 | N44: 218.46 | U44: =SUM(L44:S44) -> 573.46 | V44: =(J44+K44)-U44 -> 1926.54
B45: Mitchell, Rey John | C45: Project Supervisor | D45: 12D | E45: 8500 | G45: =E45-F45 -> 8500 | K45: 2500 | L45: 255 | M45: 100 | N45: 142.58 | U45: =SUM(L45:S45) -> 497.58 | V45: =(J45+K45)-U45 -> 2002.42
...

Sheet Sheet2

Sheet 30
B3: BACS CONSTRUCTION SERVICES AND ENGINEERING CONSULTANCY
B4: PAYROLL SUMMARY
B5: COVERED DATE : | C5: JUNE 11-25, 2022
B6: PERIOD : | C6: 44742
B8: NAME | C8: DESIGNATION | D8: Hours/Days | E8: Basic Pay | F8: Less: Absent, Late and Undertime | G8: Total Basic Pay | H8: Overtime | I8: Holiday & Premium Pay | J8: GROSS WAGE | K8: De Minimis | N8: DEDUCTIONS | T8: TOTAL DEDUCTION | U8: NET PAY
L10: SSS | M10: INSURANCE | N10: Income Tax | O10: COMM. ALLOWANCE | P10: Other Deduction | Q10: SSS Loan | R10: TRAVEL | S10: LOAN
M11: BPI
B13: Bacosa , Cesario Jr | C13: CEO/ PRESIDENT | E13: 15000 | K13: 2500 | M13: 147.17 | O13: 899.75 | P13: 5000 | R13: 500 | T13: =SUM(L13:R13) -> 6546.92 | U13: =(E13+K13)-T13 -> 10953.08
B14: Villegas, Gabby G. | C14: Project Manager | E14: 13250 | K14: 4250 | L14: 1125 | M14: 147.17 | N14: =1133.33/2 -> 566.665 | O14: =500/2 -> 250 | P14: 187.5 | R14: 1000 | S14: 2691.67 | T14: =SUM(L14:R14) -> 3276.335 | U14: =(E14+K14)-T14 -> 14223.665
B15: Germina, Mark Jayson H | C15: Operation Manager | E15: 11250 | K15: 4250 | L15: 1012.5 | M15: 147.17 | N15: =533.4/2 -> 266.7 | O15: =500/2 -> 250 | P15: 187.5 | R15: 500 | S15: 2250 | T15: =SUM(L15:R15) -> 2363.87 | U15: =(E15+K15)-T15 -> 13136.13
B16: Beltran, Lyn M. | C16: Admin Manager | E16: 12750 | K16: 4250 | L16: 1125 | M16: 147.17 | N16: =1133.33/2 -> 566.665 | O16: 250 | R16: 1700 | T16: =SUM(L16:R16) -> 3788.835 | U16: =(E16+K16)-T16 -> 13211.165
B17: Bacosa, Katherine J. | C17: Finance Manager | E17: 11000 | K17: 3500 | M17: 147.17 | O17: 837.25 | P17: 5000 | R17: 500 | T17: =SUM(L17:R17) -> 6484.42 | U17: =(E17+K17)-T17 -> 8015.58
B18: PROJECT MANAGEMENT | U18: =(E18+K18)-T18 -> 0
B19: Bocala, Kevin O. | C19: Technical Head | D19: =#REF! -> #REF! | E19: 9000 | F19: =#REF! -> #REF! | G19: =E19-F19 -> #REF! | J19: =G19+H19+I19 -> #REF! | L19: 810 | M19: 109.23 | S19: 2500 | T19: =SUM(L19:R19) -> 919.23 | U19: =(J19+K19)-T19 -> #REF!
B20: Comoso, Mayca | C20: Office Staff | D20: =COMOSO!J33 -> 74.683333 | E20: =15042.6/2 -> 7521.3 | F20: =COMOSO!N35 -> 327.69231 | G20: =E20-F20 -> 7193.6077 | I20: =COMOSO!N38 -> 1474.6154 | J20: =G20+H20+I20 -> 8668.2231 | L20: 675 | M20: 71.29 | S20: 1510 | T20: =SUM(L20:R20) -> 746.29 | U20: =(J20+K20)-T20 -> 7921.9331
B21: Dagot, Gie Boy | C21: Technical Staff | D21: =DAGOT!J36 -> 127.5 | E21: =15042.6/2 -> 7521.3 | F21: =DAGOT!N38 -> 596.79456 | G21: =E21-F21 -> 6924.5054 | I21: =DAGOT!#REF! -> #REF! | J21: =G21+H21+I21 -> #REF! | L21: 675 | M21: 71.29 | S21: 1350 | T21: =SUM(L21:R21) -> 746.29 | U21: =(J21+K21)-T21 -> #REF!
B22: Sucia, Van Lloyd | C22: Technical Staff | D22: =#REF! -> #REF! | E22: =15042.6/2 -> 7521.3 | F22: =#REF! -> #REF! | G22: =E22-F22 -> #REF! | J22: =G22+H22+I22 -> #REF! | L22: 675 | M22: 71.29 | T22: =SUM(L22:R22) -> 746.29 | U22: =(J22+K22)-T22 -> #REF!
B23: Malazarte, Jan Kayle Mari | C23: Technical Staff | D23: =#REF! -> #REF! | E23: =15042.6/2 -> 7521.3 | F23: =#REF! -> #REF! | G23: =E23-F23 -> #REF! | I23: =#REF! -> #REF! | J23: =G23+H23+I23 -> #REF! | L23: 675 | M23: 71.29 | T23: =SUM(L23:R23) -> 746.29 | U23: =(J23+K23)-T23 -> #REF!
B24: Soledad, Princess Joy | C24: Project Survey Head | D24: =#REF! -> #REF! | E24: 10250 | G24: =E24 -> 10250 | J24: =G24+H24+I24 -> 10250 | L24: 900 | M24: 109.23 | R24: 830 | S24: 1311.94 | T24: =SUM(L24:R24) -> 1839.23 | U24: =(J24+K24)-T24 -> 8410.77
B25: Batul, Shajanli Grace | C25: Procurement Officer | D25: =BATUL!G13 -> 104 | E25: 6000 | F25: =BATUL!M33 -> 0 | G25: =E25-F25 -> 6000 | H25: =BATUL!M35 -> 0 | I25: =BATUL!M36 -> 0 | J25: =G25+H25+I25 -> 6000 | L25: 540 | M25: 142.58 | S25: 833.33 | T25: =SUM(L25:R25) -> 682.58 | U25: =(J25+K25)-T25 -> 5317.42
B26: Juanich, Paul Jerome | C26: Draftsman | D26: =#REF! -> #REF! | E26: 6000 | F26: =#REF! -> #REF! | G26: =E26-F26 -> #REF! | I26: =#REF! -> #REF! | J26: =G26+H26+I26 -> #REF! | L26: 540 | M26: 142.58 | T26: =SUM(L26:R26) -> 682.58 | U26: =(J26+K26)-T26 -> #REF!
B27: Manaeg, Harold | C27: Technical Staff | D27: =ADELANTAR!J33 -> 106.38333 | E27: 6000 | F27: =ADELANTAR!N35 -> 312.28333 | G27: =E27-F27 -> 5687.7167 | H27: =ADELANTAR!N37 -> 153.75 | I27: =ADELANTAR!N38 -> 0 | J27: =G27+H27+I27 -> 5841.4667 | L27: 540 | S27: 1670 | T27: =SUM(L27:R27) -> 540 | U27: =(J27+K27)-T27 -> 5301.4667
B28: Alejandrino, Rey Mark | C28: Laboratory Operator | D28: =#REF! -> #REF! | E28: 6000 | F28: =#REF! -> #REF! | G28: =E28-F28 -> #REF! | I28: =#REF! -> #REF! | J28: =G28+H28+I28 -> #REF! | L28: 540 | T28: =SUM(L28:R28) -> 540 | U28: =(J28+K28)-T28 -> #REF!
B29: Paredes, Matthew | C29: Part Time Draftsman | D29: =#REF! -> #REF! | E29: =#REF! -> #REF! | F29: =#REF! -> #REF! | G29: =E29-F29 -> #REF! | H29: =#REF! -> #REF! | I29: =#REF! -> #REF! | J29: =G29+H29+I29 -> #REF! | U29: =(J29+K29)-T29 -> #REF!
B30: ADMIN | G30: =E30-F30 -> 0 | J30: =G30+H30+I30 -> 0 | U30: =(J30+K30)-T30 -> 0
B31: Gaid, Dorabel Y. | C31: Admin Assistant | D31: =#REF! -> #REF! | E31: 8000 | F31: =#REF! -> #REF! | G31: =E31-F31 -> #REF! | I31: =#REF! -> #REF! | J31: =G31+H31+I31 -> #REF! | L31: 720 | M31: 147.17 | Q31: 1015.19 | S31: 1600 | T31: =SUM(L31:R31) -> 1882.36 | U31: =(J31+K31)-T31 -> #REF!
B32: Guerzo, Jovelyn H. | C32: EHS Head | D32: =#REF! -> #REF! | E32: 9250 | G32: =E32-F32 -> 9250 | J32: =G32+H32+I32 -> 9250 | L32: 832.5 | M32: 109.23 | R32: 500 | S32: 1500 | T32: =SUM(L32:R32) -> 1441.73 | U32: =(J32+K32)-T32 -> 7808.27
B33: Jamelo, Elfren | C33: Amansinaya In-charge | D33: 104 | E33: 7500 | G33: =E33-F33 -> 7500 | J33: =G33+H33+I33 -> 7500 | K33: 2000 | L33: 675 | M33: 109.23 | S33: 3125 | T33: =SUM(L33:R33) -> 784.23 | U33: =(J33+K33)-T33 -> 8715.77
B34: Macatangay, Michael | C34: Company Driver | D34: 104 | E34: 7500 | G34: =E34-F34 -> 7500 | J34: =G34+H34+I34 -> 7500 | K34: 1000 | L34: 675 | M34: 142.58 | S34: 1666.63 | T34: =SUM(L34:R34) -> 817.58 | U34: =(J34+K34)-T34 -> 7682.42
B35: Galedo, Joshua | C35: General Services Staff | D35: =#REF! -> #REF! | E35: 7500 | G35: =E35-F35 -> 7500 | J35: =G35+H35+I35 -> 7500 | L35: 675 | M35: 71.29 | R35: 1000 | S35: 2500 | T35: =SUM(L35:R35) -> 1746.29 | U35: =(J35+K35)-T35 -> 5753.71
B36: Aurelio, Roderic | C36: Utility | D36: =#REF! -> #REF! | E36: 5000 | F36: =#REF! -> #REF! | G36: =E36-F36 -> #REF! | I36: =#REF! -> #REF! | J36: =G36+H36+I36 -> #REF! | L36: 450 | T36: =SUM(L36:R36) -> 450 | U36: =(J36+K36)-T36 -> #REF!
B37: Nacpil, Marilyn | C37: Consultant, EHS | E37: 5000 | J37: 5000 | U37: =(J37+K37)-T37 -> 5000
B38: Grageda, Riza | C38: Psychometrician | E38: 3000 | J38: 3000 | U38: =(J38+K38)-T38 -> 3000
B39: Bacosa, Mary Jel | C39: Consultant, Legal | E39: 3000 | J39: 3000 | R39: 1000 | S39: 1500 | U39: =(J39+K39)-T39 -> 3000
B40: FINANCE | G40: =E40-F40 -> 0 | J40: =G40+H40+I40 -> 0 | U40: =(J40+K40)-T40 -> 0
B41: Acompañado, Nancy | C41: A/R Officer | D41: =#REF! -> #REF! | E41: 8000 | G41: =E41-F41 -> 8000 | I41: =#REF! -> #REF! | J41: =G41+H41+I41 -> #REF! | L41: 720 | M41: 71.29 | P41: 292 | T41: =SUM(L41:R41) -> 1083.29 | U41: =(J41+K41)-T41 -> #REF!
B42: Consuelo, Regine | C42: Finance Assistant | D42: =#REF! -> #REF! | E42: 8500 | G42: =E42-F42 -> 8500 | J42: =G42+H42+I42 -> 8500 | L42: 765 | M42: 71.29 | P42: 292 | T42: =SUM(L42:R42) -> 1128.29 | U42: =(J42+K42)-T42 -> 7371.71
B43: Dobleros, Reden | C43: Accounting Clerk | D43: =#REF! -> #REF! | E43: 6000 | G43: =E43-F43 -> 6000 | I43: =#REF! -> #REF! | J43: =G43+H43+I43 -> #REF! | L43: 540 | M43: 142.58 | T43: =SUM(L43:R43) -> 682.58 | U43: =(J43+K43)-T43 -> #REF!
B44: OPERATION | G44: =E44-F44 -> 0 | J44: =G44+H44+I44 -> 0 | U44: =(J44+K44)-T44 -> 0
B45: Cayapas, Reymond I | C45: Project Team Leader | D45: =#REF! -> #REF! | E45: 6000 | G45: =E45-F45 -> 6000 | J45: =G45+H45+I45 -> 6000 | L45: 540 | M45: 218.46 | T45: =SUM(L45:R45) -> 758.46 | U45: =(J45+K45)-T45 -> 5241.54
...

Sheet AUG15
A3: BACS CONSTRUCTION SERVICES AND ENGINEERING CONSULTANCY
A4: PAYROLL SUMMARY
A5: COVERED DATE : | B5: Aug 11-25, 2022
A6: PERIOD : | B6: 44804
A8: NAME | B8: DESIGNATION | C8: Hours/Days | D8: Basic Pay | E8: Less: Absent, Late and Undertime | F8: Total Basic Pay | G8: Overtime | H8: Holiday & Premium Pay | I8: GROSS WAGE | J8: De Minimis | O8: DEDUCTIONS | W8: TOTAL DEDUCTION | X8: NET PAY
K10: PHIC | L10: HDMF | M10: SSS | N10: INSURANCE | O10: Income Tax | P10: COMM. ALLOWANCE | Q10: Other Deduction | R10: SSS Loan | S10: TRAVEL | T10: LOAN | U10: CASH ADVANCE | V10: FOR RETRO
N11: BPI
A13: Bacosa , Cesario Jr | B13: CEO/ PRESIDENT | D13: 15000 | F13: =D13-E13 -> 15000 | I13: =F13+G13+H13 -> 15000 | J13: 2500 | N13: 147.17 | P13: 1524.75 | Q13: 5000 | S13: 500 | U13: 9024.15 | W13: =SUM(M13:U13) -> 16196.07 | X13: =(D13+J13)-W13 -> 1303.93
A14: Villegas, Gabby G. | B14: Project Manager | D14: 13250 | F14: =D14-E14 -> 13250 | I14: =F14+G14+H14 -> 13250 | J14: 4250 | K14: 397.5 | L14: 300 | N14: 147.17 | O14: =1333.33/2 -> 666.665 | P14: 1107.75 | Q14: 187.5 | S14: 1000 | T14: 2691.67 | W14: =SUM(M14:U14) -> 5800.755 | X14: =(D14+J14)-W14 -> 11699.245
A15: Germina, Mark Jayson H | B15: Operation Manager | D15: 11250 | F15: =D15-E15 -> 11250 | I15: =F15+G15+H15 -> 11250 | J15: 4250 | K15: 337.5 | L15: 300 | N15: 147.17 | O15: =533.4/2 -> 266.7 | P15: 1107.75 | Q15: 187.5 | S15: 500 | T15: 2250 | U15: 500 | W15: =SUM(M15:U15) -> 4959.12 | X15: =(D15+J15)-W15 -> 10540.88
A16: Beltran, Lyn M. | B16: Admin Manager | D16: 12750 | F16: =D16-E16 -> 12750 | I16: =F16+G16+H16 -> 12750 | J16: 4250 | K16: 382.5 | L16: 500 | N16: 147.17 | O16: =1133.33/2 -> 566.665 | P16: 250 | S16: 1700 | W16: =SUM(M16:U16) -> 2663.835 | X16: =(D16+J16)-W16 -> 14336.165
A17: Bacosa, Katherine J. | B17: Finance Manager | D17: 11000 | F17: =D17-E17 -> 11000 | I17: =F17+G17+H17 -> 11000 | J17: 3500 | N17: 147.17 | P17: 1462.25 | Q17: 5000 | S17: 500 | U17: 1500 | W17: =SUM(M17:U17) -> 8609.42 | X17: =(D17+J17)-W17 -> 5890.58
A18: PROJECT MANAGEMENT | X18: =(D18+J18)-W18 -> 0
A19: Bocala, Kevin O. | B19: Technical Head | D19: 9000 | E19: 1384.64 | F19: =D19-E19 -> 7615.36 | I19: =F19+G19+H19 -> 7615.36 | K19: 225 | L19: 100 | N19: 109.23 | T19: 2500 | U19: 1000 | W19: =SUM(M19:U19) -> 3609.23 | X19: =(I19+J19)-W19 -> 4006.13
A20: Comoso, Mayca | B20: Office Staff | D20: 8099.84 | E20: 103.66 | F20: =D20-E20 -> 7996.18 | I20: =F20+G20+H20 -> 7996.18 | K20: 225.64 | L20: 100 | N20: 71.29 | T20: 1510 | U20: 1000 | W20: =SUM(M20:U20) -> 2581.29 | X20: =(I20+J20)-W20 -> 5414.89
A21: Dagot, Gie Boy | B21: Technical Staff | D21: 8099.84 | F21: =D21-E21 -> 8099.84 | I21: =F21+G21+H21 -> 8099.84 | K21: 225.64 | L21: 100 | N21: 71.29 | T21: 1350 | W21: =SUM(M21:U21) -> 1421.29 | X21: =(I21+J21)-W21 -> 6678.55
A22: Sucia, Van Lloyd | B22: Technical Staff | D22: 8099.84 | E22: 253.12 | F22: =D22-E22 -> 7846.72 | I22: =F22+G22+H22 -> 7846.72 | K22: 225.64 | L22: 100 | N22: 71.29 | U22: 1000 | W22: =SUM(M22:U22) -> 1071.29 | X22: =(I22+J22)-W22 -> 6775.43
A23: Malazarte, Jan Kayle Mari | B23: Technical Staff | D23: 8099.84 | E23: 335.08 | F23: =D23-E23 -> 7764.76 | I23: =F23+G23+H23 -> 7764.76 | K23: 225.64 | L23: 100 | N23: 71.29 | W23: =SUM(M23:U23) -> 71.29 | X23: =(I23+J23)-W23 -> 7693.47
A24: Soledad, Princess Joy | B24: Project Survey Head | D24: 10250 | F24: =D24-E24 -> 10250 | I24: =F24+G24+H24 -> 10250 | K24: 307.5 | L24: 100 | N24: 109.23 | S24: 830 | T24: 1311.94 | W24: =SUM(M24:U24) -> 2251.17 | X24: =(I24+J24)-W24 -> 7998.83
A25: Batul, Shajanli Grace | B25: Procurement Officer | D25: 8076.92 | E25: 843.75 | F25: =D25-E25 -> 7233.17 | G25: 540.87 | I25: =F25+G25+H25 -> 7774.04 | K25: 180 | L25: 100 | N25: 142.58 | T25: 833.33 | U25: 1000 | W25: =SUM(M25:U25) -> 1975.91 | X25: =(I25+J25)-W25 -> 5798.13
A26: Juanich, Paul Jerome | B26: Draftsman | D26: 6461.28 | E26: 1396.1 | F26: =D26-E26 -> 5065.18 | I26: =F26+G26+H26 -> 5065.18 | N26: 285.16 | W26: =SUM(M26:U26) -> 285.16 | X26: =(I26+J26)-W26 -> 4780.02
A27: Manaeg, Harold | B27: Technical Staff | C27: =ADELANTAR!J33 -> 106.38333 | D27: 6000 | E27: 1846.08 | F27: =D27-E27 -> 4153.92 | G27: 144.23 | I27: =F27+G27+H27 -> 4298.15 | K27: 180 | L27: 100 | N27: 285.16 | T27: 1670 | W27: =SUM(M27:U27) -> 1955.16 | X27: =(I27+J27)-W27 -> 2342.99
A28: Alejandrino, Rey Mark | B28: Laboratory Operator | D28: 6461.54 | E28: 230.77 | F28: =D28-E28 -> 6230.77 | I28: =F28+G28+H28 -> 6230.77 | K28: 180 | L28: 100 | N28: 171.1 | U28: 1000 | W28: =SUM(M28:U28) -> 1171.1 | X28: =(I28+J28)-W28 -> 5059.67
A29: Paredes, Matthew | B29: Part Time Draftsman | D29: 4380 | E29: 377.17 | F29: =D29-E29 -> 4002.83 | G29: =399.22+231.34 -> 630.56 | I29: =F29+G29+H29 -> 4633.39 | W29: =SUM(M29:U29) -> 0 | X29: =(I29+J29)-W29 -> 4633.39
A30: ADMIN | F30: =D30-E30 -> 0 | I30: =F30+G30+H30 -> 0 | X30: =(I30+J30)-W30 -> 0
A31: Gaid, Dorabel Y. | B31: Admin Assistant | D31: 8615.38 | E31: 907.7 | F31: =D31-E31 -> 7707.68 | I31: =F31+G31+H31 -> 7707.68 | K31: 240 | L31: 500 | N31: 147.17 | R31: 500 | T31: 1600 | U31: 1500 | W31: =SUM(M31:U31) -> 3747.17 | X31: =(I31+J31)-W31 -> 3960.51
A32: Guerzo, Jovelyn H. | B32: EHS Head | D32: 9250 | F32: =D32-E32 -> 9250 | I32: =F32+G32+H32 -> 9250 | K32: 277.5 | L32: 100 | N32: 109.23 | S32: 500 | T32: 1500 | U32: 1000 | W32: =SUM(M32:U32) -> 3109.23 | X32: =(I32+J32)-W32 -> 6140.77
A33: Grageda, Riza | B33: Psychometrician | D33: - | I33: =F33+G33+H33 -> 0 | X33: 3000
A34: Nacpil, Marilyn | B34: Consultant, EHS | D34: - | X34: 5000
A35: Bacosa, Mary Jel | B35: Consultant, Legal | D35: - | X35: 3000
A36: Jamelo, Elfren | B36: Amansinaya In-charge | D36: 7500 | F36: =D36-E36 -> 7500 | I36: =F36+G36+H36 -> 7500 | J36: 2000 | K36: 225 | N36: 109.23 | T36: 3125 | U36: 500 | W36: =SUM(M36:U36) -> 3734.23 | X36: =(I36+J36)-W36 -> 5765.77
A37: Macatangay, Michael | B37: Company Driver | D37: 7500 | F37: =D37-E37 -> 7500 | I37: =F37+G37+H37 -> 7500 | J37: 1000 | K37: 225 | L37: 100 | N37: 142.58 | T37: 1666.63 | U37: 1000 | W37: =SUM(M37:U37) -> 2809.21 | X37: =(I37+J37)-W37 -> 5690.79
A38: Galedo, Joshua | B38: General Services Staff | D38: 7500 | F38: =D38-E38 -> 7500 | I38: =F38+G38+H38 -> 7500 | K38: 225 | L38: 100 | N38: 71.29 | S38: 1000 | T38: 2500 | U38: 500 | W38: =SUM(M38:U38) -> 4071.29 | X38: =(I38+J38)-W38 -> 3428.71
A39: Aurelio, Roderic | B39: Utility | D39: 5384.62 | F39: =D39-E39 -> 5384.62 | I39: =F39+G39+H39 -> 5384.62 | K39: 150 | L39: 100 | W39: =SUM(M39:U39) -> 0 | X39: =(I39+J39)-W39 -> 5384.62
A40: FINANCE | F40: =D40-E40 -> 0 | I40: =F40+G40+H40 -> 0 | X40: =(I40+J40)-W40 -> 0
A41: Acompañado, Nancy | B41: A/R Officer | D41: 8615.38 | F41: =D41-E41 -> 8615.38 | I41: =F41+G41+H41 -> 8615.38 | K41: 240 | L41: 100 | N41: 71.29 | Q41: 292 | U41: 1000 | W41: =SUM(M41:U41) -> 1363.29 | X41: =(I41+J41)-W41 -> 7252.09
A42: Consuelo, Regine | B42: Finance Assistant | D42: 8500 | F42: =D42-E42 -> 8500 | I42: =F42+G42+H42 -> 8500 | K42: 255 | L42: 100 | N42: 71.29 | Q42: 292 | S42: 1000 | T42: 1500 | U42: 500 | W42: =SUM(M42:U42) -> 3363.29 | X42: =(I42+J42)-W42 -> 5136.71
A43: Dobleros, Reden | B43: Accounting Clerk | D43: 7277.5 | E43: 520.9 | F43: =D43-E43 -> 6756.6 | I43: =F43+G43+H43 -> 6756.6 | K43: 180 | L43: 100 | N43: 142.58 | U43: 1000 | W43: =SUM(M43:U43) -> 1142.58 | X43: =(I43+J43)-W43 -> 5614.02
A44: OPERATION | F44: =D44-E44 -> 0 | I44: =F44+G44+H44 -> 0 | X44: =(I44+J44)-W44 -> 0
A45: Calinawagan, Daryl | B45: Consultant, Material | W45: 4000 | X45: 4000
...

Sheet SEPT 30
A1: BACS CONSTRUCTION SERVICES AND ENGINEERING CONSULTANCY
A2: PAYROLL SUMMARY
A3: COVERED DATE : | B3: SEPTEMBER 11-25, 2026
A4: PERIOD : | B4: 46295
A6: NAME | B6: DESIGNATION | C6: Hours/Days | D6: Basic Pay | E6: Less: Absent, Late and Undertime | F6: Total Basic Pay | G6: Overtime | H6: Holiday & Premium Pay | I6: GROSS WAGE | J6: De Minimis | K6: DEDUCTIONS | S6: FOR RETRO | T6: TOTAL DEDUCTION | U6: NET PAY | V6: BNM SAVINGS | W6: BNM LOAN | X6: Membership Fee | Z6: BNM | AA6: SALARY
K8: SSS | L8: Income Tax | M8: Pag-ibig Loan | N8: SSS Loan | O8: RCBC Loan | P8: Medical Pooling | Q8: CASH ADVANCE | R8: Other Deduction
F15: =D15-E15 -> 0 | I15: =SUM(F15:H15) -> 0 | T15: =SUM(K15:R15) -> 0 | U15: =I15+J15+S15-T15 -> 0 | AD15: =AB15-AC15 -> 0
B16: Laboratory Operator | D16: =PAALAN!N33 -> 7000 | E16: =PAALAN!N34 -> 0 | F16: =D16-E16 -> 7000 | G16: =PAALAN!N36 -> 0 | H16: =PAALAN!N37 -> 0 | I16: =SUM(F16:H16) -> 7000 | K16: 700 | P16: 100 | S16: 0 | T16: =SUM(K16:R16) -> 800 | U16: =I16+J16+S16-T16 -> 6200 | Y16: =U16-SUM(V16:X16) -> 6200 | AB16: =Y16+Z16+AA16 -> 6200 | AC16: 5998.08 | AD16: =AB16-AC16 -> 201.92
B17: Proj. Technical Supervisor | D17: =PATRICIO!N33 -> 9216.64 | E17: =PATRICIO!N34 -> 0 | F17: =D17-E17 -> 9216.64 | H17: =PATRICIO!N37 -> 0 | I17: =SUM(F17:H17) -> 9216.64 | J17: 1500 | K17: 925 | N17: 0 | P17: 200 | T17: =SUM(K17:R17) -> 1125 | U17: =I17+J17+S17-T17 -> 9591.64 | V17: 1000 | W17: 2809.77 | Y17: =U17-SUM(V17:X17) -> 5781.87 | AB17: =Y17+Z17+AA17 -> 5781.87 | AC17: 5250.14 | AD17: =AB17-AC17 -> 531.73
B18: Junior Office Engineer | D18: ='Fixed Salary - Sample'!N32 -> 10000 | E18: ='Fixed Salary - Sample'!N33 -> 480.76923 | F18: =D18-E18 -> 9519.2308 | H18: ='Fixed Salary - Sample'!N36 -> 0 | I18: =SUM(F18:H18) -> 9519.2308 | J18: 1500 | K18: 925 | P18: 100 | Q18: 0 | T18: =SUM(K18:R18) -> 1025 | U18: =I18+J18+S18-T18 -> 9994.2308 | V18: 1000 | W18: 30 | Y18: =U18-SUM(V18:X18) -> 8964.2308 | AB18: =Y18+Z18+AA18 -> 8964.2308 | AC18: 8868.08 | AD18: =AB18-AC18 -> 96.150769
B19: Technical Staff | D19: =MALAZARTE!N33 -> 9963.4803 | E19: =MALAZARTE!N34 -> 863.50162 | F19: =D19-E19 -> 9099.9787 | G19: =MALAZARTE!N36 -> 1186.1286 | H19: =MALAZARTE!N37 -> 0 | I19: =SUM(F19:H19) -> 10286.107 | K19: 975 | N19: 800 | O19: 500 | P19: 100 | R19: 538.4 | T19: =SUM(K19:R19) -> 2913.4 | U19: =I19+J19+S19-T19 -> 7372.7073 | V19: 1000 | W19: 2000 | Y19: =U19-SUM(V19:X19) -> 4372.7073 | AB19: =Y19+Z19+AA19 -> 4372.7073 | AC19: 5262.2 | AD19: =AB19-AC19 -> -889.49273
B20: Draftsman | D20: =PAREDES!N33 -> 8661.8286 | E20: =PAREDES!N34 -> 46.746377 | F20: =D20-E20 -> 8615.0822 | G20: =PAREDES!N36 -> 1237.4041 | H20: =PAREDES!N37 -> 0 | I20: =SUM(F20:H20) -> 9852.4863 | K20: 850 | O20: 750 | P20: 100 | T20: =SUM(K20:R20) -> 1700 | U20: =I20+J20+S20-T20 -> 8152.4863 | V20: 1000 | W20: 1622.25 | Y20: =U20-SUM(V20:X20) -> 5530.2363 | AB20: =Y20+Z20+AA20 -> 5530.2363 | AC20: 4438.57 | AD20: =AB20-AC20 -> 1091.6663
B21: Technical Staff | D21: =BUNGAY!N33 -> 6562.5 | E21: =BUNGAY!N34 -> 0 | F21: =D21-E21 -> 6562.5 | G21: =BUNGAY!N36 -> 703.125 | H21: =BUNGAY!N37 -> 0 | I21: =SUM(F21:H21) -> 7265.625 | K21: 650 | O21: 0 | P21: 100 | T21: =SUM(K21:R21) -> 750 | U21: =I21+J21+S21-T21 -> 6515.625 | V21: 500 | Y21: =U21-SUM(V21:X21) -> 6015.625 | AB21: =Y21+Z21+AA21 -> 6015.625 | AC21: 6028.13 | AD21: =AB21-AC21 -> -12.505
B22: Laboratory Operator | D22: =BASA!N33 -> 8532.4161 | E22: =BASA!N34 -> 570.18209 | F22: =D22-E22 -> 7962.234 | G22: =BASA!N36 -> 0 | H22: =BASA!N37 -> 0 | I22: =SUM(F22:H22) -> 7962.234 | K22: 850 | P22: 100 | T22: =SUM(K22:R22) -> 950 | U22: =I22+J22+S22-T22 -> 7012.234 | V22: 1000 | W22: 1734.11 | Y22: =U22-SUM(V22:X22) -> 4278.124 | AB22: =Y22+Z22+AA22 -> 4278.124 | AC22: 4335.01 | AD22: =AB22-AC22 -> -56.885986
B23: Technical Staff | D23: =ADRIANO!N33 -> 6562.5 | E23: =ADRIANO!N34 -> 250 | F23: =D23-E23 -> 6312.5 | G23: =ADRIANO!N36 -> 625 | H23: =ADRIANO!N37 -> 0 | I23: =SUM(F23:H23) -> 6937.5 | K23: 650 | P23: 100 | T23: =SUM(K23:R23) -> 750 | U23: =I23+J23+S23-T23 -> 6187.5 | Y23: =U23-SUM(V23:X23) -> 6187.5 | AB23: =Y23+Z23+AA23 -> 6187.5 | AC23: 6184.38 | AD23: =AB23-AC23 -> 3.12
B24: Technical Staff | D24: =AZMAN!N33 -> 6562.5 | E24: =AZMAN!N34 -> 2937.5 | F24: =D24-E24 -> 3625 | G24: =AZMAN!N36 -> 234.375 | H24: =AZMAN!N37 -> 0 | I24: =SUM(F24:H24) -> 3859.375 | K24: 650 | P24: 100 | T24: =SUM(K24:R24) -> 750 | U24: =I24+J24+S24-T24 -> 3109.375 | Y24: =U24-SUM(V24:X24) -> 3109.375 | AB24: 0 | AD24: 0
AD25: =AB25-AC25 -> 0
B26: Jr. Sales | D26: =BARORO!N33 -> 6562.5 | E26: =BARORO!N34 -> 187.5 | F26: =D26-E26 -> 6375 | G26: =BARORO!N36 -> 1015.625 | H26: =BARORO!N37 -> 0 | I26: =SUM(F26:H26) -> 7390.625 | J26: 1300 | K26: 650 | O26: 0 | P26: 100 | T26: =SUM(K26:R26) -> 750 | U26: =I26+J26+S26-T26 -> 7940.625 | V26: 1000 | W26: 322.94 | Y26: =U26-SUM(V26:X26) -> 6617.685 | AB26: =Y26+Z26+AA26 -> 6617.685 | AC26: 5770.81 | AD26: =AB26-AC26 -> 846.875
B27: Sales & Marketing | D27: =RUIZ!N33 -> 6562.5 | E27: =RUIZ!N34 -> 3.125 | F27: =D27-E27 -> 6559.375 | G27: =RUIZ!N36 -> 1015.625 | H27: =RUIZ!N37 -> 0 | I27: =SUM(F27:H27) -> 7575 | J27: 0 | K27: 650 | O27: 0 | P27: 100 | T27: =SUM(K27:R27) -> 750 | U27: =I27+J27+S27-T27 -> 6825 | Y27: =U27-SUM(V27:X27) -> 6825 | AB27: =Y27+Z27+AA27 -> 6825 | AC27: 5981.25 | AD27: =AB27-AC27 -> 843.75
F28: =D28-E28 -> 0 | I28: =SUM(F28:H28) -> 0 | T28: =SUM(K28:R28) -> 0 | U28: =I28+J28+S28-T28 -> 0 | Y28: =U28-SUM(V28:X28) -> 0 | AB28: =Y28+Z28+AA28 -> 0 | AD28: =AB28-AC28 -> 0
B29: IT | D29: =GAID!N33 -> 9020 | E29: =GAID!N34 -> 346.92308 | F29: =D29-E29 -> 8673.0769 | G29: =GAID!N36 -> 0 | H29: =GAID!N37 -> 0 | I29: =SUM(F29:H29) -> 8673.0769 | J29: 0 | K29: 900 | L29: 0 | M29: 600 | N29: 800 | O29: 0 | P29: 200 | R29: 0 | T29: =SUM(K29:R29) -> 2500 | U29: =I29+J29+S29-T29 -> 6173.0769 | V29: 2000 | W29: 3500 | Y29: =U29-SUM(V29:X29) -> 673.07692 | AA29: =Y62 -> 7627.8846 | AB29: =Y29+Z29+AA29 -> 8300.9615 | AC29: 6788.65 | AD29: =AB29-AC29 -> 1512.3115
B30: EHS Head | D30: =GUERZO!N33 -> 10270 | E30: =GUERZO!N34 -> 0 | F30: =D30-E30 -> 10270 | H30: =GUERZO!N37 -> 0 | I30: =SUM(F30:H30) -> 10270 | J30: 2500 | K30: 1025 | N30: 1000 | O30: 3500 | P30: 100 | T30: =SUM(K30:R30) -> 5625 | U30: =I30+J30+S30-T30 -> 7145 | V30: 1000 | W30: 3500 | Y30: =U30-SUM(V30:X30) -> 2645 | AB30: =Y30+Z30+AA30 -> 2645 | AC30: 2645 | AD30: =AB30-AC30 -> 0
B31: Company Driver | D31: =MACATANGAY!N33 -> 8520 | E31: =MACATANGAY!N34 -> 0 | F31: =D31-E31 -> 8520 | H31: =MACATANGAY!N37 -> 0 | I31: =SUM(F31:H31) -> 8520 | J31: 1000 | K31: 850 | P31: 100 | Q31: 500 | R31: 250 | T31: =SUM(K31:R31) -> 1700 | U31: =I31+J31+S31-T31 -> 7820 | V31: 1000 | W31: 2061.65 | Y31: =U31-SUM(V31:X31) -> 4758.35 | AB31: =Y31+Z31+AA31 -> 4758.35 | AC31: 5008.35 | AD31: =AB31-AC31 -> -250
B32: GSS | D32: =ALEJANDRINO!N33 -> 8579.335 | E32: =ALEJANDRINO!N34 -> 0 | F32: =D32-E32 -> 8579.335 | H32: =ALEJANDRINO!N37 -> 0 | I32: =SUM(F32:H32) -> 8579.335 | J32: 1500 | K32: 850 | N32: 750 | P32: 100 | T32: =SUM(K32:R32) -> 1700 | U32: =I32+J32+S32-T32 -> 8379.335 | V32: 2000 | W32: 2668.94 | Y32: =U32-SUM(V32:X32) -> 3710.395 | AB32: =Y32+Z32+AA32 -> 3710.395 | AC32: 3710.4 | AD32: =AB32-AC32 -> -0.005
B33: Repair & Maintenance | D33: ='DELA CRUZ'!N33 -> 7067.3077 | E33: ='DELA CRUZ'!N34 -> 816.66667 | F33: =D33-E33 -> 6250.641 | G33: ='DELA CRUZ'!N36 -> 0 | H33: ='DELA CRUZ'!N37 -> 0 | I33: =SUM(F33:H33) -> 6250.641 | J33: 0 | K33: 700 | N33: 0 | P33: 100 | T33: =SUM(K33:R33) -> 800 | U33: =I33+J33+S33-T33 -> 5450.641 | V33: 1000 | W33: 961.59 | Y33: =U33-SUM(V33:X33) -> 3489.051 | AA33: =Y59 -> 3137.62 | AB33: =Y33+Z33+AA33 -> 6626.671 | AC33: 6798.15 | AD33: =AB33-AC33 -> -171.47897
B34: Staff | D34: =ABREA!N33 -> 6000 | E34: =ABREA!N34 -> 0 | F34: =D34-E34 -> 6000 | G34: =ABREA!N36 -> 312.5 | H34: =ABREA!N37 -> 0 | I34: =SUM(F34:H34) -> 6312.5 | J34: 0 | K34: 650 | P34: 100 | Q34: 750 | R34: 250 | S34: 0 | T34: =SUM(K34:R34) -> 1750 | U34: =I34+J34+S34-T34 -> 4562.5 | V34: 3000 | W34: 822.16 | Y34: =U34-SUM(V34:X34) -> 740.34 | AB34: =Y34+Z34+AA34 -> 740.34 | AC34: 1409.09 | AD34: =AB34-AC34 -> -668.75
B35: Company Driver | D35: 7500 | F35: =D35-E35 -> 7500 | I35: =SUM(F35:H35) -> 7500 | J35: 2500 | K35: 750 | P35: 100 | Q35: 0 | S35: 0 | T35: =SUM(K35:R35) -> 850 | U35: =I35+J35+S35-T35 -> 9150 | V35: 2000 | W35: 2055.41 | Y35: =U35-SUM(V35:X35) -> 5094.59 | AA35: =-Y35 -> -5094.59 | AB35: =Y35+Z35+AA35 -> 0 | AD35: =AB35-AC35 -> 0
B36: Company Driver | D36: 7500 | F36: =D36-E36 -> 7500 | I36: =SUM(F36:H36) -> 7500 | J36: 2500 | K36: 750 | P36: 100 | Q36: 1250 | T36: =SUM(K36:R36) -> 2100 | U36: =I36+J36+S36-T36 -> 7900 | Y36: =U36-SUM(V36:X36) -> 7900 | AA36: =-Y36 -> -7900 | AB36: =Y36+Z36+AA36 -> 0 | AD36: =AB36-AC36 -> 0
B37: Company Driver | D37: 7500 | F37: =D37-E37 -> 7500 | I37: =SUM(F37:H37) -> 7500 | J37: 2500 | K37: 750 | P37: 100 | Q37: 0 | T37: =SUM(K37:R37) -> 850 | U37: =I37+J37+S37-T37 -> 9150 | Y37: =U37-SUM(V37:X37) -> 9150 | AA37: =-Y37 -> -9150 | AB37: =Y37+Z37+AA37 -> 0 | AD37: =AB37-AC37 -> 0
B38: Admin Asst. | D38: =ELEAZAR!N33 -> 6562.5 | E38: =ELEAZAR!N34 -> 3750 | F38: =D38-E38 -> 2812.5 | G38: =ELEAZAR!N36 -> 468.75 | H38: =ELEAZAR!N37 -> 0 | I38: =SUM(F38:H38) -> 3281.25 | P38: 0 | T38: =SUM(K38:R38) -> 0 | U38: =I38+J38+S38-T38 -> 3281.25 | Y38: =U38-SUM(V38:X38) -> 3281.25 | AA38: 0 | AB38: 0
F39: =D39-E39 -> 0 | I39: =SUM(F39:H39) -> 0 | T39: =SUM(K39:R39) -> 0 | U39: =I39+J39+S39-T39 -> 0 | AD39: =AB39-AC39 -> 0
B40: A/R Officer | D40: =ACOMPAÑADO!N33 -> 9106.7308 | E40: =ACOMPAÑADO!N34 -> 2892.4712 | F40: =D40-E40 -> 6214.2596 | G40: =ACOMPAÑADO!N36 -> 0 | H40: =ACOMPAÑADO!N37 -> 0 | I40: =SUM(F40:H40) -> 6214.2596 | J40: 1500 | K40: 900 | M40: 600 | N40: 1000 | O40: 2000 | P40: 100 | Q40: 750 | T40: =SUM(K40:R40) -> 5350 | U40: =I40+J40+S40-T40 -> 2364.2596 | V40: 2500 | W40: 1000 | Y40: =U40-SUM(V40:X40) -> -1135.7404 | Z40: =V67+W67+X67+P64 -> 99534.05 | AB40: =Y40+Z40+AA40 -> 98398.31 | AC40: 121866.96 | AD40: =AB40-AC40 -> -23468.65
B41: Finance Assistant | D41: =CONSUELO!N33 -> 10520 | E41: =CONSUELO!N34 -> 2023.0769 | F41: =D41-E41 -> 8496.9231 | H41: =CONSUELO!N37 -> 0 | I41: =SUM(F41:H41) -> 8496.9231 | J41: 1000 | K41: 1050 | N41: 1500 | O41: 1000 | P41: 100 | Q41: 1500 | T41: =SUM(K41:R41) -> 5150 | U41: =I41+J41+S41-T41 -> 4346.9231 | V41: 2500 | W41: 2500 | Y41: =U41-SUM(V41:X41) -> -653.07692 | AB41: =Y41+Z41+AA41 -> -653.07692 | AC41: 965.38 | AD41: =AB41-AC41 -> -1618.4569
B42: Accounting Clerk | D42: ='Accntng Clerk Salary Sample '!N33 -> 8661.8286 | E42: ='Accntng Clerk Salary Sample '!N34 -> 1653.9968 | F42: =D42-E42 -> 7007.8318 | G42: ='Accntng Clerk Salary Sample '!N36 -> 412.46803 | H42: ='Accntng Clerk Salary Sample '!N37 -> 0 | I42: =SUM(F42:H42) -> 7420.2998 | K42: 850 | M42: 500 | N42: 500 | O42: 2000 | P42: 100 | T42: =SUM(K42:R42) -> 3950 | U42: =I42+J42+S42-T42 -> 3470.2998 | V42: 1500 | W42: 2000 | Y42: =U42-SUM(V42:X42) -> -29.700161 | AB42: =Y42+Z42+AA42 -> -29.700161 | AC42: 737.49 | AD42: =AB42-AC42 -> -767.19016
B43: Bookkeeper | D43: =HERRERA!N33 -> 8224.0543 | E43: =HERRERA!N34 -> 0 | F43: =D43-E43 -> 8224.0543 | G43: =HERRERA!N36 -> 0 | H43: =HERRERA!N37 -> 0 | I43: =SUM(F43:H43) -> 8224.0543 | J43: 0 | K43: 825 | N43: 1667.95 | P43: 100 | T43: =SUM(K43:R43) -> 2592.95 | U43: =I43+J43+S43-T43 -> 5631.1043 | V43: 1000 | W43: 2500 | Y43: =U43-SUM(V43:X43) -> 2131.1043 | AB43: =Y43+Z43+AA43 -> 2131.1043 | AC43: 2342.58 | AD43: =AB43-AC43 -> -211.47567
F44: =D44-E44 -> 0 | I44: =SUM(F44:H44) -> 0 | T44: =SUM(K44:R44) -> 0 | U44: =I44+J44+S44-T44 -> 0 | Y44: =U44-SUM(V44:X44) -> 0 | AB44: =Y44+Z44+AA44 -> 0 | AD44: =AB44-AC44 -> 0
B45: Field Engineer | D45: =CAYAPAS!N33 -> 10201.62 | E45: =CAYAPAS!N34 -> 0 | F45: =D45-E45 -> 10201.62 | H45: =CAYAPAS!N37 -> 0 | I45: =SUM(F45:H45) -> 10201.62 | J45: 1500 | K45: 1025 | N45: 1000 | P45: 100 | T45: =SUM(K45:R45) -> 2125 | U45: =I45+J45+S45-T45 -> 9576.62 | V45: 1000 | W45: 4000 | Y45: =U45-SUM(V45:X45) -> 4576.62 | AB45: =Y45+Z45+AA45 -> 4576.62 | AC45: 4576.62 | AD45: =AB45-AC45 -> 0
B46: Field Staff | D46: 7000 | F46: =D46-E46 -> 7000 | I46: =SUM(F46:H46) -> 7000 | J46: 2500 | K46: 600 | N46: 43.95 | P46: 100 | Q46: 1000 | T46: =SUM(K46:R46) -> 1743.95 | U46: =I46+J46+S46-T46 -> 7756.05 | V46: 1000 | Y46: =U46-SUM(V46:X46) -> 6756.05 | AB46: =Y46+Z46+AA46 -> 6756.05 | AC46: 6756.05 | AD46: =AB46-AC46 -> 0
B47: Project Team Leader | D47: 9000 | F47: =D47-E47 -> 9000 | I47: =SUM(F47:H47) -> 9000 | J47: 3000 | K47: 900 | P47: 100 | T47: =SUM(K47:R47) -> 1000 | U47: =I47+J47+S47-T47 -> 11000 | V47: 3000 | W47: 1479.89 | Y47: =U47-SUM(V47:X47) -> 6520.11 | AB47: =Y47+Z47+AA47 -> 6520.11 | AC47: 6520.11 | AD47: =AB47-AC47 -> 0
B48: Project Team Leader | D48: 9500 | F48: =D48-E48 -> 9500 | I48: =SUM(F48:H48) -> 9500 | J48: 3000 | K48: 900 | P48: 100 | Q48: 1250 | S48: 0 | T48: =SUM(K48:R48) -> 2250 | U48: =I48+J48+S48-T48 -> 10250 | V48: 1000 | W48: 3367.83 | Y48: =U48-SUM(V48:X48) -> 5882.17 | AA48: =Y36+Y61 -> 14450 | AB48: =Y48+Z48+AA48 -> 20332.17 | AC48: 20332.17 | AD48: =AB48-AC48 -> 0
...

Sheet ADMIN (2)
B7: NAME: | C7: Beltran, Lyn M. | D7: PERIOD: | E7: APRIL 25- MAY 10, 2022 | G7: NAME: | H7: Gaid, Dorabel | I7: PERIOD: | J7: =E7 -> APRIL 25- MAY 10, 2022
B8: DESIGNATION: | C8: Admin | D8: Release Date: | E8: 44696 | G8: DESIGNATION: | H8: Admin Assistant | I8: Release Date: | J8: 44696
B11: EARNINGS | D11: DEDUCTION | E11: AMOUNT | G11: EARNINGS | I11: DEDUCTION | J11: AMOUNT
B12: Basic Salary | C12: 12750 | D12: Absences/Tardiness/ Undertime | E12: #REF! | G12: Basic Salary | H12: 8000 | I12: Absences/Tardiness/ Undertime | J12: =#REF! -> #REF!
B13: De Minimis | C13: 4250 | D13: Cash Advance / Loan | E13: 3480 | G13: De Minimis | I13: Cash Advance / Loan
B14: Refund / Retro | D14: SSS | G14: Refund / Retro | I14: SSS
B15: Overtime Pay | D15: PhilHealth | E15: 382.5 | G15: Overtime Pay | H15: =#REF! -> #REF! | I15: PhilHealth
B16: Holiday Pay | D16: Pag-Ibig | E16: 500 | G16: Holiday Pay | I16: Pag-Ibig
B17: Premium Pay | D17: Income Tax | E17: 466.7 | G17: Premium Pay | I17: Income Tax
D18: Insurance/s | E18: 147.17 | I18: Insurance/s
D19: Communication Allow. | E19: 250 | I19: Communication Allow.
B21: TOTAL EARNINGS: | C21: =SUM(C12:C19) -> 17000 | D21: TOTAL DEDUCTION: | E21: =SUM(E13:E19) -> 5226.37 | G21: TOTAL EARNINGS: | H21: =SUM(H12:H19) -> #REF! | I21: TOTAL DEDUCTION: | J21: =SUM(J12:J19) -> #REF!
B23: NET PAY: | E23: =C21-E21 -> 11773.63 | G23: NET PAY: | J23: =H21-J21 -> #REF!
B25: Prepared By: | C25: Approved By: | D25: Received By | G25: Prepared By: | H25: Approved By: | I25: Received By
B27: DORABEL Y. GAID | C27: KATHERINE J. BACOSA | D27: _____________________________ | G27: DORABEL Y. GAID | H27: KATHERINE J. BACOSA | I27: _____________________________
B28: Admin Assistant | C28: Finance Manager | D28: Employee's Signature w/ Printed Name | G28: Admin Assistant | H28: Finance Manager | I28: Employee's Signature w/ Printed Name
B37: NAME: | C37: Guerzo, Jovelyn H. | D37: PERIOD: | E37: APRIL 25- MAY 10, 2022 | G37: NAME: | H37: Jamelo, Elfren | I37: PERIOD: | J37: APRIL 25- MAY 10, 2022
B38: DESIGNATION: | C38: EHS Head | D38: Release Date: | E38: 44696 | G38: DESIGNATION: | H38: Amansinaya | I38: Release Date: | J38: 44696
B40: EARNINGS | D40: DEDUCTION | E40: AMOUNT | G40: EARNINGS | I40: DEDUCTION | J40: AMOUNT
B41: Basic Salary | C41: 9250 | D41: Absences/Tardiness/ Undertime | E41: #REF! | G41: Basic Salary | H41: 7500 | I41: Absences/Tardiness/ Undertime | J41: #REF!
B42: De Minimis | D42: Cash Advance / Loan | E42: #REF! | G42: De Minimis | H42: 2000 | I42: Cash Advance / Loan | J42: #REF!
B43: Refund / Retro | D43: SSS | G43: Refund / Retro | I43: SSS
